Internal Server Error: /stationery/generate_custom_printout_report/
Traceback (most recent call last):
  File "C:\Users\chanm\Desktop\ClickPick\ClickPick\backend\env\Lib\site-packages\django\template\base.py", line 875, in _resolve_lookup
    current = current[bit]
              ~~~~~~~^^^^^
TypeError: 'FieldFile' object is not subscriptable

During handling of the above exception, another exception occurred:

Traceback (most recent call last):
  File "C:\Users\chanm\Desktop\ClickPick\ClickPick\backend\env\Lib\site-packages\django\core\handlers\exception.py", line 55, in inner
    response = get_response(request)
               ^^^^^^^^^^^^^^^^^^^^^
  File "C:\Users\chanm\Desktop\ClickPick\ClickPick\backend\env\Lib\site-packages\django\core\handlers\base.py", line 197, in _get_response
    response = wrapped_callback(request, *callback_args, **callback_kwargs)
               ^^^^^^^^^^^^^^^^^^^^^^^^^^^^^^^^^^^^^^^^^^^^^^^^^^^^^^^^^^^^
  File "C:\Users\chanm\Desktop\ClickPick\ClickPick\backend\stationery\admin_utils.py", line 147, in generate_custom_printout_report
    return render(request, 'stationery/printouts/report-pdfs.html', context)
           ^^^^^^^^^^^^^^^^^^^^^^^^^^^^^^^^^^^^^^^^^^^^^^^^^^^^^^^^^^^^^^^^^
  File "C:\Users\chanm\Desktop\ClickPick\ClickPick\backend\env\Lib\site-packages\django\shortcuts.py", line 24, in render
    content = loader.render_to_string(template_name, context, request, using=using)
              ^^^^^^^^^^^^^^^^^^^^^^^^^^^^^^^^^^^^^^^^^^^^^^^^^^^^^^^^^^^^^^^^^^^^^
  File "C:\Users\chanm\Desktop\ClickPick\ClickPick\backend\env\Lib\site-packages\django\template\loader.py", line 62, in render_to_string
    return template.render(context, request)
           ^^^^^^^^^^^^^^^^^^^^^^^^^^^^^^^^^
  File "C:\Users\chanm\Desktop\ClickPick\ClickPick\backend\env\Lib\site-packages\django\template\backends\django.py", line 61, in render
    return self.template.render(context)
           ^^^^^^^^^^^^^^^^^^^^^^^^^^^^^
  File "C:\Users\chanm\Desktop\ClickPick\ClickPick\backend\env\Lib\site-packages\django\template\base.py", line 171, in render
    return self._render(context)
           ^^^^^^^^^^^^^^^^^^^^^
  File "C:\Users\chanm\Desktop\ClickPick\ClickPick\backend\env\Lib\site-packages\django\template\base.py", line 163, in _render
    return self.nodelist.render(context)
           ^^^^^^^^^^^^^^^^^^^^^^^^^^^^^
  File "C:\Users\chanm\Desktop\ClickPick\ClickPick\backend\env\Lib\site-packages\django\template\base.py", line 1000, in render
    return SafeString("".join([node.render_annotated(context) for node in self]))
                              ^^^^^^^^^^^^^^^^^^^^^^^^^^^^^^^^^^^^^^^^^^^^^^^^^
  File "C:\Users\chanm\Desktop\ClickPick\ClickPick\backend\env\Lib\site-packages\django\template\base.py", line 1000, in <listcomp>
    return SafeString("".join([node.render_annotated(context) for node in self]))
                               ^^^^^^^^^^^^^^^^^^^^^^^^^^^^^^
  File "C:\Users\chanm\Desktop\ClickPick\ClickPick\backend\env\Lib\site-packages\django\template\base.py", line 961, in render_annotated
    return self.render(context)
           ^^^^^^^^^^^^^^^^^^^^
  File "C:\Users\chanm\Desktop\ClickPick\ClickPick\backend\env\Lib\site-packages\django\template\defaulttags.py", line 241, in render
    nodelist.append(node.render_annotated(context))
                    ^^^^^^^^^^^^^^^^^^^^^^^^^^^^^^
  File "C:\Users\chanm\Desktop\ClickPick\ClickPick\backend\env\Lib\site-packages\django\template\base.py", line 961, in render_annotated
    return self.render(context)
           ^^^^^^^^^^^^^^^^^^^^
  File "C:\Users\chanm\Desktop\ClickPick\ClickPick\backend\env\Lib\site-packages\django\template\base.py", line 1059, in render
    output = self.filter_expression.resolve(context)
             ^^^^^^^^^^^^^^^^^^^^^^^^^^^^^^^^^^^^^^^
  File "C:\Users\chanm\Desktop\ClickPick\ClickPick\backend\env\Lib\site-packages\django\template\base.py", line 710, in resolve
    obj = self.var.resolve(context)
          ^^^^^^^^^^^^^^^^^^^^^^^^^
  File "C:\Users\chanm\Desktop\ClickPick\ClickPick\backend\env\Lib\site-packages\django\template\base.py", line 842, in resolve
    value = self._resolve_lookup(context)
            ^^^^^^^^^^^^^^^^^^^^^^^^^^^^^
  File "C:\Users\chanm\Desktop\ClickPick\ClickPick\backend\env\Lib\site-packages\django\template\base.py", line 885, in _resolve_lookup
    current = getattr(current, bit)
              ^^^^^^^^^^^^^^^^^^^^^
  File "C:\Users\chanm\Desktop\ClickPick\ClickPick\backend\env\Lib\site-packages\django\db\models\fields\files.py", line 66, in url
    self._require_file()
  File "C:\Users\chanm\Desktop\ClickPick\ClickPick\backend\env\Lib\site-packages\django\db\models\fields\files.py", line 41, in _require_file
    raise ValueError(
ValueError: The 'file' attribute has no file associated with it.
"POST /stationery/generate_custom_printout_report/ HTTP/1.1" 500 160044
Internal Server Error: /stationery/printout-reports/daily/
Traceback (most recent call last):
  File "C:\Users\chanm\Desktop\ClickPick\ClickPick\backend\env\Lib\site-packages\django\core\handlers\exception.py", line 55, in inner
    response = get_response(request)
               ^^^^^^^^^^^^^^^^^^^^^
  File "C:\Users\chanm\Desktop\ClickPick\ClickPick\backend\env\Lib\site-packages\django\core\handlers\base.py", line 197, in _get_response
    response = wrapped_callback(request, *callback_args, **callback_kwargs)
               ^^^^^^^^^^^^^^^^^^^^^^^^^^^^^^^^^^^^^^^^^^^^^^^^^^^^^^^^^^^^
  File "C:\Users\chanm\Desktop\ClickPick\ClickPick\backend\stationery\admin_utils.py", line 115, in generate_printout_report
    start_date = timezone.make_aware(start_date_naive, timezone=server_timezone)
                 ^^^^^^^^^^^^^^^^^^^^^^^^^^^^^^^^^^^^^^^^^^^^^^^^^^^^^^^^^^^^^^^
  File "C:\Users\chanm\Desktop\ClickPick\ClickPick\backend\env\Lib\site-packages\django\utils\timezone.py", line 242, in make_aware
    if is_aware(value):
       ^^^^^^^^^^^^^^^
  File "C:\Users\chanm\Desktop\ClickPick\ClickPick\backend\env\Lib\site-packages\django\utils\timezone.py", line 221, in is_aware
    return value.utcoffset() is not None
           ^^^^^^^^^^^^^^^
AttributeError: 'datetime.date' object has no attribute 'utcoffset'
"GET /stationery/printout-reports/daily/ HTTP/1.1" 500 83628
Internal Server Error: /stationery/generate-firstpage/
Traceback (most recent call last):
  File "C:\Users\aman\AppData\Local\Programs\Python\Python312\Lib\site-packages\django\db\backends\utils.py", line 89, in _execute
    return self.cursor.execute(sql, params)
           ^^^^^^^^^^^^^^^^^^^^^^^^^^^^^^^^
  File "C:\Users\aman\AppData\Local\Programs\Python\Python312\Lib\site-packages\django\db\backends\sqlite3\base.py", line 328, in execute
    return super().execute(query, params)
           ^^^^^^^^^^^^^^^^^^^^^^^^^^^^^^
sqlite3.OperationalError: no such table: users

The above exception was the direct cause of the following exception:

Traceback (most recent call last):
  File "C:\Users\aman\AppData\Local\Programs\Python\Python312\Lib\site-packages\django\core\handlers\exception.py", line 55, in inner
    response = get_response(request)
               ^^^^^^^^^^^^^^^^^^^^^
  File "C:\Users\aman\AppData\Local\Programs\Python\Python312\Lib\site-packages\django\core\handlers\base.py", line 197, in _get_response
    response = wrapped_callback(request, *callback_args, **callback_kwargs)
               ^^^^^^^^^^^^^^^^^^^^^^^^^^^^^^^^^^^^^^^^^^^^^^^^^^^^^^^^^^^^
  File "C:\Users\aman\AppData\Local\Programs\Python\Python312\Lib\site-packages\django\views\decorators\csrf.py", line 56, in wrapper_view
    return view_func(*args, **kwargs)
           ^^^^^^^^^^^^^^^^^^^^^^^^^^
  File "C:\Users\aman\AppData\Local\Programs\Python\Python312\Lib\site-packages\django\views\generic\base.py", line 104, in view
    return self.dispatch(request, *args, **kwargs)
           ^^^^^^^^^^^^^^^^^^^^^^^^^^^^^^^^^^^^^^^
  File "C:\Users\aman\AppData\Local\Programs\Python\Python312\Lib\site-packages\rest_framework\views.py", line 509, in dispatch
    response = self.handle_exception(exc)
               ^^^^^^^^^^^^^^^^^^^^^^^^^^
  File "C:\Users\aman\AppData\Local\Programs\Python\Python312\Lib\site-packages\rest_framework\views.py", line 469, in handle_exception
    self.raise_uncaught_exception(exc)
  File "C:\Users\aman\AppData\Local\Programs\Python\Python312\Lib\site-packages\rest_framework\views.py", line 480, in raise_uncaught_exception
    raise exc
  File "C:\Users\aman\AppData\Local\Programs\Python\Python312\Lib\site-packages\rest_framework\views.py", line 497, in dispatch
    self.initial(request, *args, **kwargs)
  File "C:\Users\aman\AppData\Local\Programs\Python\Python312\Lib\site-packages\rest_framework\views.py", line 414, in initial
    self.perform_authentication(request)
  File "C:\Users\aman\AppData\Local\Programs\Python\Python312\Lib\site-packages\rest_framework\views.py", line 324, in perform_authentication
    request.user
  File "C:\Users\aman\AppData\Local\Programs\Python\Python312\Lib\site-packages\rest_framework\request.py", line 227, in user
    self._authenticate()
  File "C:\Users\aman\AppData\Local\Programs\Python\Python312\Lib\site-packages\rest_framework\request.py", line 380, in _authenticate
    user_auth_tuple = authenticator.authenticate(self)
                      ^^^^^^^^^^^^^^^^^^^^^^^^^^^^^^^^
  File "C:\Users\aman\AppData\Local\Programs\Python\Python312\Lib\site-packages\rest_framework_simplejwt\authentication.py", line 51, in authenticate
    return self.get_user(validated_token), validated_token
           ^^^^^^^^^^^^^^^^^^^^^^^^^^^^^^
  File "C:\Users\aman\AppData\Local\Programs\Python\Python312\Lib\site-packages\rest_framework_simplejwt\authentication.py", line 130, in get_user
    user = self.user_model.objects.get(**{api_settings.USER_ID_FIELD: user_id})
           ^^^^^^^^^^^^^^^^^^^^^^^^^^^^^^^^^^^^^^^^^^^^^^^^^^^^^^^^^^^^^^^^^^^^
  File "C:\Users\aman\AppData\Local\Programs\Python\Python312\Lib\site-packages\django\db\models\manager.py", line 87, in manager_method
    return getattr(self.get_queryset(), name)(*args, **kwargs)
           ^^^^^^^^^^^^^^^^^^^^^^^^^^^^^^^^^^^^^^^^^^^^^^^^^^^
  File "C:\Users\aman\AppData\Local\Programs\Python\Python312\Lib\site-packages\django\db\models\query.py", line 633, in get
    num = len(clone)
          ^^^^^^^^^^
  File "C:\Users\aman\AppData\Local\Programs\Python\Python312\Lib\site-packages\django\db\models\query.py", line 380, in __len__
    self._fetch_all()
  File "C:\Users\aman\AppData\Local\Programs\Python\Python312\Lib\site-packages\django\db\models\query.py", line 1881, in _fetch_all
    self._result_cache = list(self._iterable_class(self))
                         ^^^^^^^^^^^^^^^^^^^^^^^^^^^^^^^^
  File "C:\Users\aman\AppData\Local\Programs\Python\Python312\Lib\site-packages\django\db\models\query.py", line 91, in __iter__
    results = compiler.execute_sql(
              ^^^^^^^^^^^^^^^^^^^^^
  File "C:\Users\aman\AppData\Local\Programs\Python\Python312\Lib\site-packages\django\db\models\sql\compiler.py", line 1562, in execute_sql
    cursor.execute(sql, params)
  File "C:\Users\aman\AppData\Local\Programs\Python\Python312\Lib\site-packages\django\db\backends\utils.py", line 102, in execute
    return super().execute(sql, params)
           ^^^^^^^^^^^^^^^^^^^^^^^^^^^^
  File "C:\Users\aman\AppData\Local\Programs\Python\Python312\Lib\site-packages\django\db\backends\utils.py", line 67, in execute
    return self._execute_with_wrappers(
           ^^^^^^^^^^^^^^^^^^^^^^^^^^^^
  File "C:\Users\aman\AppData\Local\Programs\Python\Python312\Lib\site-packages\django\db\backends\utils.py", line 80, in _execute_with_wrappers
    return executor(sql, params, many, context)
           ^^^^^^^^^^^^^^^^^^^^^^^^^^^^^^^^^^^^
  File "C:\Users\aman\AppData\Local\Programs\Python\Python312\Lib\site-packages\django\db\backends\utils.py", line 84, in _execute
    with self.db.wrap_database_errors:
  File "C:\Users\aman\AppData\Local\Programs\Python\Python312\Lib\site-packages\django\db\utils.py", line 91, in __exit__
    raise dj_exc_value.with_traceback(traceback) from exc_value
  File "C:\Users\aman\AppData\Local\Programs\Python\Python312\Lib\site-packages\django\db\backends\utils.py", line 89, in _execute
    return self.cursor.execute(sql, params)
           ^^^^^^^^^^^^^^^^^^^^^^^^^^^^^^^^
  File "C:\Users\aman\AppData\Local\Programs\Python\Python312\Lib\site-packages\django\db\backends\sqlite3\base.py", line 328, in execute
    return super().execute(query, params)
           ^^^^^^^^^^^^^^^^^^^^^^^^^^^^^^
django.db.utils.OperationalError: no such table: users
"POST /stationery/generate-firstpage/ HTTP/1.1" 500 193752
